{
  "_annotation": {
    "cve_id": "CVE-2024-4030",
    "reason": "Added CPE configurations because not yet analyzed by NVD.",
    "snapshot": "https://raw.githubusercontent.com/anchore/nvd-data-overrides/main/.snapshot/2024/CVE-2024-4030.json",
    "triage_notes": {
      "references": [
        "https://mail.python.org/archives/list/security-announce@python.org/thread/PRGS5OR3N3PNPT4BMV2VAGN5GMUI5636/",
        "https://github.com/python/cpython/issues/118486",
        "https://github.com/python/cpython/commit/8ed546679524140d8282175411fd141fe7df070d",
        "https://github.com/python/cpython/commit/81939dad77001556c527485d31a2d0f4a759033e"
      ]
    }
  },
  "cve": {
    "configurations": [
      {
        "nodes": [
          {
            "cpeMatch": [
              {
                "criteria": "cpe:2.3:a:python:python:*:*:*:*:*:*:*:*",
                "matchCriteriaId": "3005A594-3F99-564F-AC81-786CB2E974C8",
                "versionEndExcluding": "3.13.0b1",
                "versionStartIncluding": "3.13.0a1",
                "vulnerable": true
              },
              {
                "criteria": "cpe:2.3:a:python:python:*:*:*:*:*:*:*:*",
                "matchCriteriaId": "B2E4B428-578A-5ADB-A7FB-E3055BFC6587",
                "versionEndExcluding": "3.12.4",
                "vulnerable": true
              }
            ],
            "negate": false,
            "operator": "OR"
          }
        ]
      }
    ]
  }
}